<?xml version="1.0" ?>
<robot name="p73_walker" xmlns:xacro="http://www.ros.org/wiki/xacro">

<material name="silver">
  <color rgba="0.8 0.8 0.8 1.0"/>
</material>
<material name="blue">
  <color rgba="0.0 0.0 1.0 1.0"/>
</material>
<material name="white">
  <color rgba="1.0 1.0 1.0 1.0"/>
</material>

<mujoco>
  <compiler discardvisual="false" meshdir="../meshes"/> 
</mujoco>

<xacro:include filename="$(find p73_walker_description)/urdf/materials.xacro" />
<xacro:include filename="$(find p73_walker_description)/urdf/p73_walker.trans" />
<xacro:include filename="$(find p73_walker_description)/urdf/p73_walker.gazebo" />

<link name="base_link">
  <inertial>
    <origin xyz="0.0011842285436917948 8.432370048734322e-05 0.021862262922827842" rpy="0 0 0"/>
    <mass value="5.475055271656153"/>
    <inertia ixx="0.020903" iyy="0.032396" izz="0.02625" ixy="-3.8e-05" iyz="-2.3e-05" ixz="-0.000452"/>
  </inertial>
  <visual>
    <origin xyz="0 0 0" rpy="0 0 0"/>
    <geometry>
      <mesh filename="../meshes/base_link.stl" scale="0.001 0.001 0.001"/>
    </geometry>
    <material name="blue"/>
  </visual>
  <collision>
    <origin xyz="0 0 0" rpy="0 1.5708 0"/>
    <geometry>
      <cylinder radius="0.065" length="0.21"/>
    </geometry>
  </collision>
</link>

<link name="WaistYaw_Link">
  <inertial>
    <origin xyz="-0.0022513948718781472 0.0002027608554956971 0.24393253542400453" rpy="0 0 0"/>
    <mass value="7.605387605261044"/>
    <inertia ixx="0.205765" iyy="0.194816" izz="0.054731" ixy="-0.000163" iyz="-8.8e-05" ixz="0.002048"/>
  </inertial>
  <visual>
    <origin xyz="0.0 -0.0 -0.0955" rpy="0 0 0"/>
    <geometry>
      <mesh filename="../meshes/WaistYaw_Link.stl" scale="0.001 0.001 0.001"/>
    </geometry>
    <material name="white"/>
  </visual>
  <collision>
    <origin xyz="0.0 0.0 0.0385" rpy="0 0 0"/>
    <geometry>
      <cylinder radius="0.065" length="0.04"/>
    </geometry>
  </collision>
  <collision>
    <origin xyz="0.005 0.0 0.28" rpy="0 0 0"/>
    <geometry>
      <box size="0.26 0.3 0.4"/>
    </geometry>
  </collision>
</link>

<link name="R_HipRoll_Link">
  <inertial>
    <origin xyz="-0.013862584239846147 -0.0455749889811795 -0.0001384549931362008" rpy="0 0 0"/>
    <mass value="1.1787850921827068"/>
    <inertia ixx="0.001976" iyy="0.001175" izz="0.001749" ixy="-0.000147" iyz="-1.5e-05" ixz="-4e-06"/>
  </inertial>
  <visual>
    <origin xyz="-0.0155 0.0 -0.0" rpy="0 0 0"/>
    <geometry>
      <mesh filename="../meshes/R_HipRoll_Link.stl" scale="0.001 0.001 0.001"/>
    </geometry>
    <material name="blue"/>
  </visual>

</link>

<link name="L_HipRoll_Link">
  <inertial>
    <origin xyz="0.012419731496113967 0.04909393861286611 -0.00012737496889216325" rpy="0 0 0"/>
    <mass value="1.2702673584378412"/>
    <inertia ixx="0.00205" iyy="0.001251" izz="0.001807" ixy="-0.000114" iyz="1.5e-05" ixz="-3e-06"/>
  </inertial>
  <visual>
    <origin xyz="0.0155 -0.0 -0.0" rpy="0 0 0"/>
    <geometry>
      <mesh filename="../meshes/L_HipRoll_Link.stl" scale="0.001 0.001 0.001"/>
    </geometry>
    <material name="blue"/>
  </visual>

</link>

<link name="R_HipPitch_Link">
  <inertial>
    <origin xyz="0.004712639615517446 -0.04636214559106945 -0.06728800327075261" rpy="0 0 0"/>
    <mass value="6.857456505757582"/>
    <inertia ixx="0.056934" iyy="0.063984" izz="0.028187" ixy="8.9e-05" iyz="0.002894" ixz="0.000599"/>
  </inertial>
  <visual>
    <origin xyz="0.0 0.0805 -0.0" rpy="0 0 0"/>
    <geometry>
      <mesh filename="../meshes/R_HipPitch_Link.stl" scale="0.001 0.001 0.001"/>
    </geometry>
    <material name="white"/>
  </visual>
  <collision>
    <origin xyz="0.015 -0.0425 -0.06" rpy="0 0 0"/>
    <geometry>
      <box size="0.2 0.11 0.26"/>
    </geometry>
  </collision>
</link>

<link name="L_HipPitch_Link">
  <inertial>
    <origin xyz="0.0047125504252527785 0.0463623215438851 -0.06728834870778778" rpy="0 0 0"/>
    <mass value="6.857435533216696"/>
    <inertia ixx="0.056934" iyy="0.063984" izz="0.028187" ixy="-8.9e-05" iyz="-0.002894" ixz="0.000599"/>
  </inertial>
  <visual>
    <origin xyz="0.0 -0.0805 -0.0" rpy="0 0 0"/>
    <geometry>
      <mesh filename="../meshes/L_HipPitch_Link.stl" scale="0.001 0.001 0.001"/>
    </geometry>
    <material name="white"/>
  </visual>
  <collision>
    <origin xyz="0.015 0.0425 -0.06" rpy="0 0 0"/>
    <geometry>
      <box size="0.2 0.11 0.26"/>
    </geometry>
  </collision>
</link>

<link name="R_Thigh_Link">
  <inertial>
    <origin xyz="0.006719451851442015 0.0031827323714122974 -0.09173878082642711" rpy="0 0 0"/>
    <mass value="4.995693817886645"/>
    <inertia ixx="0.036534" iyy="0.040864" izz="0.024919" ixy="8.5e-05" iyz="-0.000217" ixz="-0.002949"/>
  </inertial>
  <visual>
    <origin xyz="0.0 0.1205 0.202" rpy="0 0 0"/>
    <geometry>
      <mesh filename="../meshes/R_Thigh_Link.stl" scale="0.001 0.001 0.001"/>
    </geometry>
    <material name="white"/>
  </visual>
  <collision>
    <origin xyz="0.02 0.0 -0.09" rpy="0 0 0"/>
    <geometry>
      <box size="0.2 0.14 0.16"/>
    </geometry>
  </collision>
</link>

<link name="L_Thigh_Link">
  <inertial>
    <origin xyz="0.0068771470224690354 -0.002496063039066132 -0.0919431417204869" rpy="0 0 0"/>
    <mass value="4.903279724820187"/>
    <inertia ixx="0.03632" iyy="0.040764" izz="0.024713" ixy="-5.6e-05" iyz="0.000179" ixz="-0.002958"/>
  </inertial>
  <visual>
    <origin xyz="0.0 -0.1205 0.202" rpy="0 0 0"/>
    <geometry>
      <mesh filename="../meshes/L_Thigh_Link.stl" scale="0.001 0.001 0.001"/>
    </geometry>
    <material name="white"/>
  </visual>
  <collision>
    <origin xyz="0.02 0.0 -0.09" rpy="0 0 0"/>
    <geometry>
      <box size="0.2 0.14 0.16"/>
    </geometry>
  </collision>
</link>

<link name="R_Knee_Link">
  <inertial>
    <origin xyz="0.05717709435414651 -0.018245675546185655 -0.1668289280983979" rpy="0 0 0"/>
    <mass value="7.966815282700452"/>
    <inertia ixx="0.127903" iyy="0.130292" izz="0.016806" ixy="0.00014" iyz="0.001621" ixz="-0.004715"/>
  </inertial>
  <visual>
    <origin xyz="0.042753 0.101 0.400462" rpy="0 0 0"/>
    <geometry>
      <mesh filename="../meshes/R_Knee_Link.stl" scale="0.001 0.001 0.001"/>
    </geometry>
    <material name="white"/>
  </visual>
  <collision>
    <origin xyz="0.055 -0.02 -0.12" rpy="0 0 0"/>
    <geometry>
      <box size="0.12 0.12 0.24"/>
    </geometry>
  </collision>
  <collision>
    <origin xyz="0.045 -0.02 -0.32" rpy="0 0 0"/>
    <geometry>
      <box size="0.09 0.08 0.16"/>
    </geometry>
  </collision>
</link>

<link name="L_Knee_Link">
  <inertial>
    <origin xyz="0.05644458938899081 0.01814628327082532 -0.16616216541343665" rpy="0 0 0"/>
    <mass value="8.18144928150599"/>
    <inertia ixx="0.131752" iyy="0.134467" izz="0.017186" ixy="-0.000119" iyz="-0.001734" ixz="-0.004155"/>
  </inertial>
  <visual>
    <origin xyz="0.042753 -0.101 0.400462" rpy="0 0 0"/>
    <geometry>
      <mesh filename="../meshes/L_Knee_Link.stl" scale="0.001 0.001 0.001"/>
    </geometry>
    <material name="white"/>
  </visual>
  <collision>
    <origin xyz="0.055 0.02 -0.12" rpy="0 0 0"/>
    <geometry>
      <box size="0.12 0.12 0.24"/>
    </geometry>
  </collision>
  <collision>
    <origin xyz="0.045 0.02 -0.32" rpy="0 0 0"/>
    <geometry>
      <box size="0.09 0.08 0.16"/>
    </geometry>
  </collision>
</link>

<link name="L_AnkleRoll_Link">
  <inertial>
    <origin xyz="-0.0005386333108031429 0.02349994432953678 -0.0011364775598364796" rpy="0 0 0"/>
    <mass value="0.16126824126437989"/>
    <inertia ixx="5.4e-05" iyy="3.2e-05" izz="6.8e-05" ixy="0.0" iyz="0.0" ixz="0.0"/>
  </inertial>
  <visual>
    <origin xyz="-0.000889 -0.0985 0.816317" rpy="0 0 0"/>
    <geometry>
      <mesh filename="../meshes/L_AnkleRoll_Link.stl" scale="0.001 0.001 0.001"/>
    </geometry>
    <material name="white"/>
  </visual>
  <collision>
    <origin xyz="-0.000889 -0.0985 0.816317" rpy="0 0 0"/>
    <geometry>
      <mesh filename="../meshes/L_AnkleRoll_Link.stl" scale="0.001 0.001 0.001"/>
    </geometry>
  </collision>
</link>

<link name="R_AnkleRoll_Link">
  <inertial>
    <origin xyz="-0.0005386316843018626 -0.02350005567062366 -0.0011364792268565571" rpy="0 0 0"/>
    <mass value="0.16126824126437989"/>
    <inertia ixx="5.4e-05" iyy="3.2e-05" izz="6.8e-05" ixy="0.0" iyz="0.0" ixz="0.0"/>
  </inertial>
  <visual>
    <origin xyz="-0.000889 0.0985 0.816317" rpy="0 0 0"/>
    <geometry>
      <mesh filename="../meshes/R_AnkleRoll_Link.stl" scale="0.001 0.001 0.001"/>
    </geometry>
    <material name="white"/>
  </visual>
  <collision>
    <origin xyz="-0.000889 0.0985 0.816317" rpy="0 0 0"/>
    <geometry>
      <mesh filename="../meshes/R_AnkleRoll_Link.stl" scale="0.001 0.001 0.001"/>
    </geometry>
  </collision>
</link>

<link name="L_Foot_Link">
  <inertial>
    <origin xyz="0.03907885195239992 8.77120817643906e-09 -0.06263935817946986" rpy="0 0 0"/>
    <mass value="2.3290372118414675"/>
    <inertia ixx="0.002541" iyy="0.012898" izz="0.014359" ixy="-0.0" iyz="-0.0" ixz="0.000527"/>
  </inertial>
  <visual>
    <origin xyz="-0.011889 -0.122 0.816317" rpy="0 0 0"/>
    <geometry>
      <mesh filename="../meshes/L_Foot_Link.stl" scale="0.001 0.001 0.001"/>
    </geometry>
    <material name="blue"/>
  </visual>
  <collision>
    <origin xyz="0.1 0.0 -0.067" rpy="0 0 0"/>
    <geometry>
      <box size="0.2 0.1 0.02"/>
    </geometry>
  </collision>
  <collision>
    <origin xyz="-0.03 0.0 -0.067" rpy="0 0 0"/>
    <geometry>
      <box size="0.06 0.1 0.02"/>
    </geometry>
  </collision>
</link>

<link name="R_Foot_Link">
  <inertial>
    <origin xyz="0.03907885523490258 7.205352606232118e-09 -0.06263936109178803" rpy="0 0 0"/>
    <mass value="2.3290370755141745"/>
    <inertia ixx="0.002541" iyy="0.012898" izz="0.014359" ixy="-0.0" iyz="-0.0" ixz="0.000527"/>
  </inertial>
  <visual>
    <origin xyz="-0.011889 0.122 0.816317" rpy="0 0 0"/>
    <geometry>
      <mesh filename="../meshes/R_Foot_Link.stl" scale="0.001 0.001 0.001"/>
    </geometry>
    <material name="blue"/>
  </visual>
  <collision>
    <origin xyz="0.1 0.0 -0.067" rpy="0 0 0"/>
    <geometry>
      <box size="0.2 0.1 0.02"/>
    </geometry>
  </collision>
  <collision>
    <origin xyz="-0.03 0.0 -0.067" rpy="0 0 0"/>
    <geometry>
      <box size="0.06 0.1 0.02"/>
    </geometry>
  </collision>
</link>

<joint name="WaistYaw_Joint" type="revolute">
  <origin xyz="0.0 0.0 0.0955" rpy="0 0 0"/>
  <parent link="base_link"/>
  <child link="WaistYaw_Link"/>
  <axis xyz="0.0 0.0 1.0"/>
  <limit lower="-1.57" upper="1.57" velocity="10" effort="152.0"/>
</joint>

<joint name="R_HipRoll_Joint" type="revolute">
  <origin xyz="0.0155 0.0 0.0" rpy="0 0 0"/>
  <parent link="base_link"/>
  <child link="R_HipRoll_Link"/>
  <axis xyz="-1.0 0.0 0.0"/>
  <limit lower="-0.58" upper="0.3" velocity="10" effort="352.0"/>
</joint>

<joint name="L_HipRoll_Joint" type="revolute">
  <origin xyz="-0.0155 0.0 0.0" rpy="0 0 0"/>
  <parent link="base_link"/>
  <child link="L_HipRoll_Link"/>
  <axis xyz="1.0 0.0 0.0"/>
  <limit lower="-0.58" upper="0.3" velocity="10" effort="352.0"/>
</joint>

<joint name="R_HipPitch_Joint" type="revolute">
  <origin xyz="-0.0155 -0.0805 0.0" rpy="0 0 0"/>
  <parent link="R_HipRoll_Link"/>
  <child link="R_HipPitch_Link"/>
  <axis xyz="-0.0 1.0 -0.0"/>
  <limit lower="-2.09" upper="1.57" velocity="10" effort="220.0"/>
</joint>

<joint name="L_HipPitch_Joint" type="revolute">
  <origin xyz="0.0155 0.0805 0.0" rpy="0 0 0"/>
  <parent link="L_HipRoll_Link"/>
  <child link="L_HipPitch_Link"/>
  <axis xyz="-0.0 -1.0 -0.0"/>
  <limit lower="-1.57" upper="2.09" velocity="10" effort="220.0"/>
</joint>

<joint name="R_HipYaw_Joint" type="revolute">
  <origin xyz="0.0 -0.04 -0.202" rpy="0 0 0"/>
  <parent link="R_HipPitch_Link"/>
  <child link="R_Thigh_Link"/>
  <axis xyz="0.0 0.0 -1.0"/>
  <limit lower="-0.78" upper="0.78" velocity="10" effort="95.0"/>
</joint>

<joint name="L_HipYaw_Joint" type="revolute">
  <origin xyz="0.0 0.04 -0.202" rpy="0 0 0"/>
  <parent link="L_HipPitch_Link"/>
  <child link="L_Thigh_Link"/>
  <axis xyz="0.0 -0.0 -1.0"/>
  <limit lower="-0.78" upper="0.78" velocity="10" effort="95.0"/>
</joint>

<joint name="R_Knee_Joint" type="revolute">
  <origin xyz="-0.042753 0.0195 -0.198462" rpy="0 0 0"/>
  <parent link="R_Thigh_Link"/>
  <child link="R_Knee_Link"/>
  <axis xyz="0.0 -1.0 0.0"/>
  <limit lower="-2.56" upper="0" velocity="10" effort="220.0"/>
</joint>

<joint name="L_Knee_Joint" type="revolute">
  <origin xyz="-0.042753 -0.0195 -0.198462" rpy="0 0 0"/>
  <parent link="L_Thigh_Link"/>
  <child link="L_Knee_Link"/>
  <axis xyz="0.0 1.0 -0.0"/>
  <limit lower="0" upper="2.56" velocity="10" effort="220.0"/>
</joint>

<joint name="L_AnklePitch_Joint" type="revolute">
  <origin xyz="0.043642 -0.0025 -0.415855" rpy="0 0 0"/>
  <parent link="L_Knee_Link"/>
  <child link="L_AnkleRoll_Link"/>
  <axis xyz="0.0 1.0 -0.0"/>
  <limit lower="-1.05" upper="0.7" velocity="10" effort="95"/>
</joint>

<joint name="R_AnklePitch_Joint" type="revolute">
  <origin xyz="0.043642 0.0025 -0.415855" rpy="0 0 0"/>
  <parent link="R_Knee_Link"/>
  <child link="R_AnkleRoll_Link"/>
  <axis xyz="0.0 -1.0 -0.0"/>
  <limit lower="-0.7" upper="1.05" velocity="10" effort="95"/>
</joint>

<joint name="L_AnkleRoll_Joint" type="revolute">
  <origin xyz="0.011 0.0235 0.0" rpy="0 0 0"/>
  <parent link="L_AnkleRoll_Link"/>
  <child link="L_Foot_Link"/>
  <axis xyz="1.0 0.0 0.0"/>
  <limit lower="-0.42" upper="0.42" velocity="10" effort="95"/>
</joint>

<joint name="R_AnkleRoll_Joint" type="revolute">
  <origin xyz="0.011 -0.0235 0.0" rpy="0 0 0"/>
  <parent link="R_AnkleRoll_Link"/>
  <child link="R_Foot_Link"/>
  <axis xyz="1.0 0.0 0.0"/>
  <limit lower="-0.42" upper="0.42" velocity="10" effort="95"/>
</joint>

</robot>
